[2025-06-02T14:14:41.578+0000] {taskinstance.py:1956} INFO - Dependencies all met for dep_context=non-requeueable deps ti=<TaskInstance: test_minio_http_conn.check_minio_http manual__2025-06-02T14:14:38.975127+00:00 [queued]>
[2025-06-02T14:14:41.606+0000] {taskinstance.py:1956} INFO - Dependencies all met for dep_context=requeueable deps ti=<TaskInstance: test_minio_http_conn.check_minio_http manual__2025-06-02T14:14:38.975127+00:00 [queued]>
[2025-06-02T14:14:41.607+0000] {taskinstance.py:2170} INFO - Starting attempt 1 of 1
[2025-06-02T14:14:41.630+0000] {taskinstance.py:2191} INFO - Executing <Task(PythonOperator): check_minio_http> on 2025-06-02 14:14:38.975127+00:00
[2025-06-02T14:14:41.650+0000] {standard_task_runner.py:87} INFO - Running: ['***', 'tasks', 'run', 'test_minio_http_conn', 'check_minio_http', 'manual__2025-06-02T14:14:38.975127+00:00', '--job-id', '2', '--raw', '--subdir', 'DAGS_FOLDER/test_minio.py', '--cfg-path', '/tmp/tmpsuijglg0']
[2025-06-02T14:14:41.646+0000] {standard_task_runner.py:60} INFO - Started process 185 to run task
[2025-06-02T14:14:41.658+0000] {standard_task_runner.py:88} INFO - Job 2: Subtask check_minio_http
[2025-06-02T14:14:41.760+0000] {logging_mixin.py:188} WARNING - /home/***/.local/lib/python3.8/site-packages/***/settings.py:194 DeprecationWarning: The sql_alchemy_conn option in [core] has been moved to the sql_alchemy_conn option in [database] - the old setting has been used, but please update your config.
[2025-06-02T14:14:41.885+0000] {task_command.py:423} INFO - Running <TaskInstance: test_minio_http_conn.check_minio_http manual__2025-06-02T14:14:38.975127+00:00 [running]> on host 29e48b8100b6
[2025-06-02T14:14:42.074+0000] {taskinstance.py:2480} INFO - Exporting env vars: AIRFLOW_CTX_DAG_OWNER='***' AIRFLOW_CTX_DAG_ID='test_minio_http_conn' AIRFLOW_CTX_TASK_ID='check_minio_http' AIRFLOW_CTX_EXECUTION_DATE='2025-06-02T14:14:38.975127+00:00' AIRFLOW_CTX_TRY_NUMBER='1' AIRFLOW_CTX_DAG_RUN_ID='manual__2025-06-02T14:14:38.975127+00:00'
[2025-06-02T14:14:42.087+0000] {base_aws.py:581} WARNING - Unable to find AWS Connection ID 'minio_http_conn', switching to empty.
[2025-06-02T14:14:42.088+0000] {base_aws.py:161} INFO - No connection ID provided. Fallback on boto3 credential strategy (region_name=None). See: https://boto3.amazonaws.com/v1/documentation/api/latest/guide/configuration.html
[2025-06-02T14:14:45.961+0000] {taskinstance.py:2698} ERROR - Task failed with exception
Traceback (most recent call last):
  File "/home/airflow/.local/lib/python3.8/site-packages/airflow/models/taskinstance.py", line 433, in _execute_task
    result = execute_callable(context=context, **execute_callable_kwargs)
  File "/home/airflow/.local/lib/python3.8/site-packages/airflow/operators/python.py", line 199, in execute
    return_value = self.execute_callable()
  File "/home/airflow/.local/lib/python3.8/site-packages/airflow/operators/python.py", line 216, in execute_callable
    return self.python_callable(*self.op_args, **self.op_kwargs)
  File "/opt/airflow/dags/test_minio.py", line 10, in check_minio_via_http
    if not hook.check_for_bucket(bucket):
  File "/home/airflow/.local/lib/python3.8/site-packages/airflow/providers/amazon/aws/hooks/s3.py", line 91, in wrapper
    return func(*bound_args.args, **bound_args.kwargs)
  File "/home/airflow/.local/lib/python3.8/site-packages/airflow/providers/amazon/aws/hooks/s3.py", line 281, in check_for_bucket
    self.get_conn().head_bucket(Bucket=bucket_name)
  File "/home/airflow/.local/lib/python3.8/site-packages/botocore/client.py", line 553, in _api_call
    return self._make_api_call(operation_name, kwargs)
  File "/home/airflow/.local/lib/python3.8/site-packages/botocore/client.py", line 989, in _make_api_call
    http, parsed_response = self._make_request(
  File "/home/airflow/.local/lib/python3.8/site-packages/botocore/client.py", line 1015, in _make_request
    return self._endpoint.make_request(operation_model, request_dict)
  File "/home/airflow/.local/lib/python3.8/site-packages/botocore/endpoint.py", line 119, in make_request
    return self._send_request(request_dict, operation_model)
  File "/home/airflow/.local/lib/python3.8/site-packages/botocore/endpoint.py", line 198, in _send_request
    request = self.create_request(request_dict, operation_model)
  File "/home/airflow/.local/lib/python3.8/site-packages/botocore/endpoint.py", line 134, in create_request
    self._event_emitter.emit(
  File "/home/airflow/.local/lib/python3.8/site-packages/botocore/hooks.py", line 412, in emit
    return self._emitter.emit(aliased_event_name, **kwargs)
  File "/home/airflow/.local/lib/python3.8/site-packages/botocore/hooks.py", line 256, in emit
    return self._emit(event_name, kwargs)
  File "/home/airflow/.local/lib/python3.8/site-packages/botocore/hooks.py", line 239, in _emit
    response = handler(**kwargs)
  File "/home/airflow/.local/lib/python3.8/site-packages/botocore/signers.py", line 105, in handler
    return self.sign(operation_name, request)
  File "/home/airflow/.local/lib/python3.8/site-packages/botocore/signers.py", line 195, in sign
    auth.add_auth(request)
  File "/home/airflow/.local/lib/python3.8/site-packages/botocore/auth.py", line 418, in add_auth
    raise NoCredentialsError()
botocore.exceptions.NoCredentialsError: Unable to locate credentials
[2025-06-02T14:14:46.046+0000] {taskinstance.py:1138} INFO - Marking task as FAILED. dag_id=test_minio_http_conn, task_id=check_minio_http, execution_date=20250602T141438, start_date=20250602T141441, end_date=20250602T141446
[2025-06-02T14:14:46.076+0000] {standard_task_runner.py:107} ERROR - Failed to execute job 2 for task check_minio_http (Unable to locate credentials; 185)
[2025-06-02T14:14:46.122+0000] {local_task_job_runner.py:234} INFO - Task exited with return code 1
[2025-06-02T14:14:46.225+0000] {taskinstance.py:3280} INFO - 0 downstream tasks scheduled from follow-on schedule check
