[2025-06-02T14:36:18.065+0000] {taskinstance.py:1956} INFO - Dependencies all met for dep_context=non-requeueable deps ti=<TaskInstance: test_minio_http_conn.check_minio_http manual__2025-06-02T14:36:16.455677+00:00 [queued]>
[2025-06-02T14:36:18.094+0000] {taskinstance.py:1956} INFO - Dependencies all met for dep_context=requeueable deps ti=<TaskInstance: test_minio_http_conn.check_minio_http manual__2025-06-02T14:36:16.455677+00:00 [queued]>
[2025-06-02T14:36:18.096+0000] {taskinstance.py:2170} INFO - Starting attempt 1 of 1
[2025-06-02T14:36:18.150+0000] {taskinstance.py:2191} INFO - Executing <Task(PythonOperator): check_minio_http> on 2025-06-02 14:36:16.455677+00:00
[2025-06-02T14:36:18.171+0000] {standard_task_runner.py:60} INFO - Started process 178 to run task
[2025-06-02T14:36:18.178+0000] {standard_task_runner.py:87} INFO - Running: ['***', 'tasks', 'run', 'test_minio_http_conn', 'check_minio_http', 'manual__2025-06-02T14:36:16.455677+00:00', '--job-id', '40', '--raw', '--subdir', 'DAGS_FOLDER/test_minio.py', '--cfg-path', '/tmp/tmp_8zvigay']
[2025-06-02T14:36:18.188+0000] {standard_task_runner.py:88} INFO - Job 40: Subtask check_minio_http
[2025-06-02T14:36:18.236+0000] {logging_mixin.py:188} WARNING - /home/***/.local/lib/python3.8/site-packages/***/settings.py:194 DeprecationWarning: The sql_alchemy_conn option in [core] has been moved to the sql_alchemy_conn option in [database] - the old setting has been used, but please update your config.
[2025-06-02T14:36:18.310+0000] {task_command.py:423} INFO - Running <TaskInstance: test_minio_http_conn.check_minio_http manual__2025-06-02T14:36:16.455677+00:00 [running]> on host 9e2aa634badd
[2025-06-02T14:36:18.548+0000] {taskinstance.py:2480} INFO - Exporting env vars: AIRFLOW_CTX_DAG_OWNER='***' AIRFLOW_CTX_DAG_ID='test_minio_http_conn' AIRFLOW_CTX_TASK_ID='check_minio_http' AIRFLOW_CTX_EXECUTION_DATE='2025-06-02T14:36:16.455677+00:00' AIRFLOW_CTX_TRY_NUMBER='1' AIRFLOW_CTX_DAG_RUN_ID='manual__2025-06-02T14:36:16.455677+00:00'
[2025-06-02T14:36:18.610+0000] {base.py:83} INFO - Using connection ID 'minio_con' for task execution.
[2025-06-02T14:36:18.615+0000] {logging_mixin.py:188} WARNING - <string>:9 AirflowProviderDeprecationWarning: Host http://minio:9000 specified in the connection is not used. Please, set it on extra['endpoint_url'] instead
[2025-06-02T14:36:22.554+0000] {taskinstance.py:2698} ERROR - Task failed with exception
Traceback (most recent call last):
  File "/home/airflow/.local/lib/python3.8/site-packages/airflow/models/taskinstance.py", line 433, in _execute_task
    result = execute_callable(context=context, **execute_callable_kwargs)
  File "/home/airflow/.local/lib/python3.8/site-packages/airflow/operators/python.py", line 199, in execute
    return_value = self.execute_callable()
  File "/home/airflow/.local/lib/python3.8/site-packages/airflow/operators/python.py", line 216, in execute_callable
    return self.python_callable(*self.op_args, **self.op_kwargs)
  File "/opt/airflow/dags/test_minio.py", line 10, in check_minio_via_http
    if not hook.check_for_bucket(bucket):
  File "/home/airflow/.local/lib/python3.8/site-packages/airflow/providers/amazon/aws/hooks/s3.py", line 91, in wrapper
    return func(*bound_args.args, **bound_args.kwargs)
  File "/home/airflow/.local/lib/python3.8/site-packages/airflow/providers/amazon/aws/hooks/s3.py", line 281, in check_for_bucket
    self.get_conn().head_bucket(Bucket=bucket_name)
  File "/home/airflow/.local/lib/python3.8/site-packages/botocore/client.py", line 553, in _api_call
    return self._make_api_call(operation_name, kwargs)
  File "/home/airflow/.local/lib/python3.8/site-packages/botocore/client.py", line 989, in _make_api_call
    http, parsed_response = self._make_request(
  File "/home/airflow/.local/lib/python3.8/site-packages/botocore/client.py", line 1015, in _make_request
    return self._endpoint.make_request(operation_model, request_dict)
  File "/home/airflow/.local/lib/python3.8/site-packages/botocore/endpoint.py", line 119, in make_request
    return self._send_request(request_dict, operation_model)
  File "/home/airflow/.local/lib/python3.8/site-packages/botocore/endpoint.py", line 198, in _send_request
    request = self.create_request(request_dict, operation_model)
  File "/home/airflow/.local/lib/python3.8/site-packages/botocore/endpoint.py", line 134, in create_request
    self._event_emitter.emit(
  File "/home/airflow/.local/lib/python3.8/site-packages/botocore/hooks.py", line 412, in emit
    return self._emitter.emit(aliased_event_name, **kwargs)
  File "/home/airflow/.local/lib/python3.8/site-packages/botocore/hooks.py", line 256, in emit
    return self._emit(event_name, kwargs)
  File "/home/airflow/.local/lib/python3.8/site-packages/botocore/hooks.py", line 239, in _emit
    response = handler(**kwargs)
  File "/home/airflow/.local/lib/python3.8/site-packages/botocore/signers.py", line 105, in handler
    return self.sign(operation_name, request)
  File "/home/airflow/.local/lib/python3.8/site-packages/botocore/signers.py", line 195, in sign
    auth.add_auth(request)
  File "/home/airflow/.local/lib/python3.8/site-packages/botocore/auth.py", line 418, in add_auth
    raise NoCredentialsError()
botocore.exceptions.NoCredentialsError: Unable to locate credentials
[2025-06-02T14:36:22.586+0000] {taskinstance.py:1138} INFO - Marking task as FAILED. dag_id=test_minio_http_conn, task_id=check_minio_http, execution_date=20250602T143616, start_date=20250602T143618, end_date=20250602T143622
[2025-06-02T14:36:22.610+0000] {standard_task_runner.py:107} ERROR - Failed to execute job 40 for task check_minio_http (Unable to locate credentials; 178)
[2025-06-02T14:36:22.625+0000] {local_task_job_runner.py:234} INFO - Task exited with return code 1
[2025-06-02T14:36:22.680+0000] {taskinstance.py:3280} INFO - 0 downstream tasks scheduled from follow-on schedule check
